Traceback (most recent call last):
  File "C:\Users\jesus\miniconda3\envs\testml_env\lib\site-packages\nbclient\client.py", line 778, in _async_poll_for_reply
    msg = await ensure_async(self.kc.shell_channel.get_msg(timeout=new_timeout))
  File "C:\Users\jesus\miniconda3\envs\testml_env\lib\site-packages\jupyter_core\utils\__init__.py", line 198, in ensure_async
    result = await obj
  File "C:\Users\jesus\miniconda3\envs\testml_env\lib\site-packages\jupyter_client\channels.py", line 313, in get_msg
    raise Empty
_queue.Empty

During handling of the above exception, another exception occurred:

Traceback (most recent call last):
  File "C:\Users\jesus\miniconda3\envs\testml_env\lib\site-packages\jupyter_cache\executors\utils.py", line 58, in single_nb_execution
    executenb(
  File "C:\Users\jesus\miniconda3\envs\testml_env\lib\site-packages\nbclient\client.py", line 1305, in execute
    return NotebookClient(nb=nb, resources=resources, km=km, **kwargs).execute()
  File "C:\Users\jesus\miniconda3\envs\testml_env\lib\site-packages\jupyter_core\utils\__init__.py", line 165, in wrapped
    return loop.run_until_complete(inner)
  File "C:\Users\jesus\miniconda3\envs\testml_env\lib\asyncio\base_events.py", line 616, in run_until_complete
    return future.result()
  File "C:\Users\jesus\miniconda3\envs\testml_env\lib\site-packages\nbclient\client.py", line 705, in async_execute
    await self.async_execute_cell(
  File "C:\Users\jesus\miniconda3\envs\testml_env\lib\site-packages\nbclient\client.py", line 1001, in async_execute_cell
    exec_reply = await self.task_poll_for_reply
  File "C:\Users\jesus\miniconda3\envs\testml_env\lib\site-packages\nbclient\client.py", line 802, in _async_poll_for_reply
    error_on_timeout_execute_reply = await self._async_handle_timeout(timeout, cell)
  File "C:\Users\jesus\miniconda3\envs\testml_env\lib\site-packages\nbclient\client.py", line 852, in _async_handle_timeout
    raise CellTimeoutError.error_from_timeout_and_cell(
nbclient.exceptions.CellTimeoutError: A cell timed out while it was being executed, after 30 seconds.
The message was: Cell execution timed out.
Here is a preview of the cell contents:
-------------------
['# === Optimal Number of Trees (n_estimators) Search ===', '', '# Base Random Forest model without hyperparameter tuning', 'rf_model = RandomForestRegressor(random_state=42)', '']
...
['grid_rf.fit(X_train, y_train)', '', '# Print the best number of trees (n_estimators) and the corresponding R² score', 'print("Best number of trees:", grid_rf.best_params_[\'n_estimators\'])  # Optimal n_estimators', 'print("Best R² from cross-validation:", round(grid_rf.best_score_, 4))  # Best R² score']
-------------------

